Workbook

Sheet Man
A1: Deel I. Welk antwoord verwoordt het best hoe u zich meestal voelt of gedraagt ?
A2: Kruis het vierkantje aan naast het alternatief dat u verkiest.
A4: 1. | B4: Bent u doorgaans | O4: 11. | P4: Als u in een groep bent, zult u meestal liever | W4: 20. | X4: In een grote groep zal u vaker | AN4: E | AO4: I | AP4: S | AQ4: N | AR4: T | AS4: F | AT4: J | AU4: P
C6: zeer contactvaardig | Q6: deelnemen aan het groepsgesprek | Y6: anderen voorstellen | AH6: E : | AI6: =B6*2 -> 0 | AJ6: =P6*1 -> 0 | AK6: =X6*2 -> 0 | AN6: =SUM(AI6:AK6) -> 0
C7: of | Q7: of | Y7: of
C8: eerder stil en terughoudend ? | Q8: met één persoon terzelfdertijd praten ? | Y8: voorgesteld worden ? | AH8: I : | AI8: =B8*2 -> 0 | AJ8: =P8*2 -> 0 | AK8: =X8*2 -> 0 | AO8: =SUM(AI8:AK8) -> 0
A10: 2. | B10: Als u een leraar zou zijn, zou u dan liever | O10: 12. | P10: Hebt u meer bewondering voor mensen | W10: 21. | X10: Wordt u eerder beschouwd
C12: praktijkcursussen geven | Q12: die zo gewoon zijn dat ze nooit opvallen | Y12: als een praktisch ingesteld persoon | AH12: S : | AI12: =B12*2 -> 0 | AJ12: =P12*1 -> 0 | AK12: =X12*2 -> 0 | AP12: =SUM(AI12:AK12) -> 0
C13: of | Q13: of | Y13: of
C14: theoretische cursussen geven ? | Q14: die te origineel en bijzonder zijn om zich | Y14: als een zeer vindingrijk persoon ? | AH14: N : | AI14: =B14*2 -> 0 | AJ14: =P14*2 -> 0 | AK14: =X14*2 -> 0 | AQ14: =SUM(AI14:AK14) -> 0
Q15: druk te maken of ze al dan niet opvallen ?
A17: 3. | B17: Is het een mooier compliment om | O17: 13. | P17: U laat zich leiden | W17: 22. | X17: Waardeert u meestal
B18: getypeerd te worden
C19: als een gevoelsmens | Q19: door uw gevoelens, | Y19: gevoelens meer dan logica | AH19: F : | AI19: =B19*1 -> 0 | AJ19: =P19*1 -> 0 | AK19: =X19*2 -> 0 | AS19: =SUM(AI19:AK19) -> 0
C20: of | Q20: eerder dan door uw verstand, of | Y20: of
C21: als een verstandig persoon ? | Q21: door uw verstand, | Y21: logica meer dan gevoelens ? | AH21: T : | AI21: =B21*2 -> 0 | AJ21: =P21*1 -> 0 | AK21: =X21*2 -> 0 | AR21: =SUM(AI21:AK21) -> 0
Q22: eerder dan door uw gevoelens ?
W23: 23. | X23: Als goed op voorhand geregeld is dat u
A24: 4. | B24: Als u een uitstapje maakt, zou u eerder | O24: 14. | P24: Geeft u er de voorkeur aan | X24: bepaalde dingen zal doen op een bepaald
X25: ogenblik, dan vindt u dat
C26: plannen wat u zal doen en wanneer | Q26: afspraakjes, feestjes enz. | Y26: leuk omdat u zo een aangepaste planning | AH26: J : | AI26: =B26*2 -> 0 | AJ26: =P26*2 -> 0 | AK26: =X26*1 -> 0 | AT26: =SUM(AI26:AK26) -> 0
C27: of | Q27: goed op voorhand vast te leggen, of | Y27: kan maken, of
C28: gewoon vertrekken ? | Q28: vrij te zijn om te doen wat plezierig lijkt | Y28: een beetje onplezierig om gebonden te zijn ? | AH28: P : | AI28: =B28*2 -> 0 | AJ28: =P28*1 -> 0 | AK28: =X28*1 -> 0 | AU28: =SUM(AI28:AK28) -> 0
Q29: als de gelegenheid zich voordoet ?
A31: 5. | B31: Heeft u | O31: 15. | P31: Binnen uw vriendenkring bent u | W31: 24. | X31: Praat u zonder moeite
C33: een hechte vriendschap met een | Q33: één van de laatsten die hoort | Y33: enkel met bepaalde personen of in | AH33: I : | AI33: =B33*1 -> 0 | AJ33: =P33*1 -> 0 | AK33: =X33*2 -> 0 | AO33: =SUM(AI33:AK33) -> 0
C34: zeer kleine groep mensen, of | Q34: wat er gebeurt, of | Y34: specifieke omstandigheden, of
C35: een uitgebreide vriendenkring ? | Q35: iemand die alle nieuwtjes weet ? | Y35: met om het even wie zolang als nodig is ? | AH35: E : | AI35: =B35*2 -> 0 | AJ35: =P35*2 -> 0 | AK35: =X35*2 -> 0 | AN35: =SUM(AI35:AK35) -> 0
A38: 6. | B38: Een planning volgen | O38: 16. | P38: Het idee om een lijst te maken van wat u | W38: 25. | X38: Als u op zaterdagochtend zou gevraagd worden
P39: in het weekend moet doen | X39: wat u die dag zal doen, zou u
C40: trekt u aan | Q40: trekt u aan | Y40: dit vrij goed kunnen vertellen | AH40: J : | AI40: =B40*2 -> 0 | AJ40: =P40*1 -> 0 | AK40: =X40*0 -> 0 | AT40: =SUM(AI40:AK40) -> 0
C41: of | Q41: of | Y41: of
C42: spreekt u niet aan ? | Q42: laat u koud, of | Y42: twee keer teveel zaken opnoemen, of | AH42: P : | AI42: =B42*2 -> 0 | AJ42: =P42*1 -> 0 | AK42: =X42*1 -> 0 | AU42: =SUM(AI42:AK42,AJ43:AK43) -> 0
Q43: ontmoedigt u beslist ? | Y43: moeten afwachten en zien ? | AJ43: =P43*1 -> 0 | AK43: =X43*1 -> 0
A45: 7. | B45: Schiet u meestal beter op met | O45: 17. | P45: Als vriend kiest u eerder iemand | W45: 26. | X45: Bij ontspannende literatuur, geniet u
C47: verbeeldingsrijke mensen | Q47: die steeds met nieuwe ideeën komt | Y47: van een ongewone en originele schrijfstijl | AH47: N : | AI47: =B47*2 -> 0 | AJ47: =P47*1 -> 0 | AK47: =X47*0 -> 0 | AQ47: =SUM(AI47:AK47) -> 0
C48: of | Q48: of | Y48: of
C49: realistische mensen ? | Q49: die met twee voeten op de grond staat ? | Y49: van schrijvers die precies zeggen | AH49: S : | AI49: =B49*1 -> 0 | AJ49: =P49*2 -> 0 | AK49: =X49*1 -> 0 | AP49: =SUM(AI49:AK49) -> 0
Y50: wat ze bedoelen ?
A53: 8. | B53: Heeft u het moeilijk om zich aan te passen | O53: 18. | P53: Bent u meer succesvol | W53: 27. | X53: Is het zo
...

Sheet Samenvatting
A8: MBTI-profiel voor :
A10: Beste
A12: U hebt een vragenlijst ingevuld waarmee wij uw voorkeuren op verschillende dimensies
A13: berekend hebben.
A15: Deze dimensies zijn :
A17: STIMULEREN : | F17: Waar u energie uit haalt.
B19: E : | C19: Extravert | F19: Extraversie
F20: Voorkeur om energie te halen uit de buitenwereld van mensen, activiteiten,
F21: dingen.
B23: I : | C23: Introvert | F23: Introversie
F24: Voorkeur om energie te halen uit de interne wereld van ideeën, emoties en
F25: indrukken.
A27: WAARNEMEN : | F27: Waar u aandacht aan schenkt.
B29: S : | C29: Sensing | F29: Observatie
F30: Voorkeur om informatie te verwerven door gebruik van de vijf zintuigen en
F31: aandacht te schenken aan het bestaande.
B33: N : | C33: iNtuition | F33: Intuïtie
F34: Voorkeur om informatie te verwerven door gebruik van het zesde zintuig en
F35: aandacht te schenken aan 'wat zou kunnen'.
A37: BESLISSEN : | F37: Hoe u beslist.
B39: T : | C39: Thinking | F39: Reflectie
F40: Voorkeur om informatie voor het nemen van beslissingen te organiseren en
F41: te structureren op een logische en objectieve wijze.
B43: F : | C43: Feeling | F43: Gevoel
F44: Voorkeur om informatie voor het nemen van beslissingen te organiseren en
F45: te structureren op een persoonlijke en waardegeladen wijze.
A47: LEVEN : | F47: Uw levensstijl.
B49: J : | C49: Judging | F49: Beheersing
F50: Voorkeur voor een gestructureerd en georganiseerd leven.
B52: P : | C52: Perceiving | F52: Perceptie
F53: Voorkeur voor een spontaan en flexibel leven.
A56: Bij uw lettercode staan cijfers vermeld die aangeven hoe duidelijk uw voorkeur voor die dimensie is :
A57: 1 = Lichte voorkeur | G57: Waarschijnlijk twijfelt u welke voorkeur u het meest hebt.
A58: 2 = Gematigde voorkeur | G58: Waarschijnlijk herkent u deze voorkeur, maar ook veel van de andere kant.
A59: 3 = Duidelijke voorkeur | G59: Waarschijnlijk bent u het eens met deze voorkeur.
A60: 4 = Heel duidelijke voorkeur | G60: Is er nog twijfel mogelijk ?
A62: Uw MBTI-profiel : | I62: =Man!AC216 -> I | J62: =IF(Man!AF233<=9,1,IF(Man!AF233<=19,2,IF(Man!AF233<=39,3,4))) -> 1 | K62: =Man!AD216 -> N | L62: =IF(Man!AF235<=9,1,IF(Man!AF235<=19,2,IF(Man!AF235<=39,3,4))) -> 1 | M62: =Man!AE216 -> T | N62: =IF((M62="T")*AND(Man!AF237<=9),1,IF((M62="T")*AND(Man!AF237<=19),2,IF((M62="T")*AND(Man!AF237<=39),3,IF((M62="T")*AND(Man!AF237>39),4,IF((M62="F")*AND(Man!AF237<=9),1,IF((M62="F")*AND(Man!AF237<=19),2,IF((M62="F")*AND(Man!AF237<=31),3,4))))))) -> 1 | O62: =Man!AF216 -> P | P62: =IF(Man!AF239<=9,1,IF(Man!AF239<=19,2,IF(Man!AF239<=39,3,4))) -> 1
